Workbook

Sheet HuongDan
A1: FILE THỰC HÀNH EXCEL: VLOOKUP • SUMIFS • COUNTIFS
A2: Làm lần lượt từ trái sang phải. Ô VÀNG = bạn gõ công thức. Ô XANH LÁ = ví dụ mẫu đã làm sẵn.
A4: Cách dùng file
A5: 1. Xem dữ liệu ở sheet DuLieu (50 đơn hàng) và DanhMuc (sản phẩm, nhân viên, bảng thưởng).
A6: 2. Vào từng sheet BT_..., đọc ví dụ mẫu (bấm vào ô xanh để xem công thức), rồi gõ công thức vào ô vàng.
A7: 3. Cột "Kiểm tra" tự báo ✔ Đúng / ✘ Sai. Sai thì đọc cột Gợi ý và thử lại trước khi xem sheet DapAn.
A9: Ghi nhớ nhanh
A10: VLOOKUP | B10: =VLOOKUP(giá_trị_tìm, bảng, số_thứ_tự_cột, FALSE) — FALSE = tìm chính xác; TRUE = dò gần đúng (bảng phải sắp xếp tăng dần). Cột tìm phải nằm BÊN TRÁI bảng.
A11: SUMIFS | B11: =SUMIFS(vùng_cần_cộng, vùng_đk1, đk1, vùng_đk2, đk2, …) — vùng cần cộng đứng ĐẦU TIÊN.
A12: COUNTIFS | B12: =COUNTIFS(vùng_đk1, đk1, vùng_đk2, đk2, …) — đếm số dòng thỏa TẤT CẢ điều kiện.
A13: Điều kiện so sánh | B13: Viết trong ngoặc kép: ">5", "<>Hà Nội". Ghép với ô/hàm bằng &: ">="&DATE(2026,2,1) hoặc ">"&H2
A14: Ký tự đại diện | B14: * = chuỗi bất kỳ, ? = 1 ký tự. VD "*Thị*" = có chữ Thị ở bất kỳ đâu.
A15: Dấu $ (cố định ô) | B15: F4 để chuyển: $A$2 (cố định cả hai), $A2 (cố định cột), A$2 (cố định dòng). Bảng tìm/vùng dữ liệu nên cố định $ để kéo công thức không bị lệch.
A16: Dấu phân cách | B16: Nếu Excel báo lỗi công thức, máy bạn có thể dùng dấu chấm phẩy ( ; ) thay cho dấu phẩy ( , ).
A18: Bảng điểm
A19: Bài | B19: Số câu đúng / tổng
A20: VLOOKUP | B20: =COUNTIF(BT_VLOOKUP!G7:G13,"✔*")+COUNTIF(BT_VLOOKUP!E19:E23,"✔*")+COUNTIF(BT_VLOOKUP!E29:E33,"✔*")&" / 17" -> 0 / 17
A21: SUMIFS | B21: =COUNTIF(BT_SUMIFS!F6:F12,"✔*")+IF(LEFT(BT_SUMIFS!B21,1)="✔",1,0)&" / 8" -> 0 / 8
A22: COUNTIFS | B22: =COUNTIF(BT_COUNTIFS!F6:F12,"✔*")+IF(LEFT(BT_COUNTIFS!B23,1)="✔",1,0)&" / 8" -> 0 / 8
A23: (Mỗi bảng tổng hợp tính là 1 câu, đúng khi tất cả các ô đều đúng.)

Sheet DuLieu
A1: Mã đơn | B1: Ngày | C1: Nhân viên | D1: Khu vực | E1: Mã SP | F1: Nhóm hàng | G1: Số lượng | H1: Đơn giá | I1: Thành tiền
A2: DH001 | B2: 46023 | C2: Lê Hoàng Cường | D2: Đà Nẵng | E2: SP05 | F2: Phụ kiện | G2: 3 | H2: 2100000 | I2: 6300000
A3: DH002 | B3: 46026 | C3: Hoàng Thị Em | D3: TP.HCM | E3: SP06 | F3: Văn phòng | G3: 2 | H3: 4500000 | I3: 9000000
A4: DH003 | B4: 46028 | C4: Trần Thị Bình | D4: Hà Nội | E4: SP01 | F4: Điện tử | G4: 3 | H4: 15500000 | I4: 46500000
A5: DH004 | B5: 46029 | C5: Hoàng Thị Em | D5: TP.HCM | E5: SP06 | F5: Văn phòng | G5: 2 | H5: 4500000 | I5: 9000000
A6: DH005 | B6: 46030 | C6: Phạm Thu Dung | D6: TP.HCM | E6: SP02 | F6: Phụ kiện | G6: 4 | H6: 350000 | I6: 1400000
A7: DH006 | B7: 46033 | C7: Trần Thị Bình | D7: Hà Nội | E7: SP03 | F7: Phụ kiện | G7: 5 | H7: 1200000 | I7: 6000000
A8: DH007 | B8: 46033 | C8: Phạm Thu Dung | D8: TP.HCM | E8: SP07 | F8: Văn phòng | G8: 10 | H8: 75000 | I8: 750000
A9: DH008 | B9: 46033 | C9: Trần Thị Bình | D9: Hà Nội | E9: SP04 | F9: Điện tử | G9: 3 | H9: 3800000 | I9: 11400000
A10: DH009 | B10: 46035 | C10: Hoàng Thị Em | D10: TP.HCM | E10: SP02 | F10: Phụ kiện | G10: 6 | H10: 350000 | I10: 2100000
A11: DH010 | B11: 46036 | C11: Phạm Thu Dung | D11: TP.HCM | E11: SP07 | F11: Văn phòng | G11: 20 | H11: 75000 | I11: 1500000
A12: DH011 | B12: 46036 | C12: Trần Thị Bình | D12: Hà Nội | E12: SP02 | F12: Phụ kiện | G12: 6 | H12: 350000 | I12: 2100000
A13: DH012 | B13: 46037 | C13: Nguyễn Văn An | D13: Hà Nội | E13: SP08 | F13: Điện tử | G13: 8 | H13: 9200000 | I13: 73600000
... A51: DH050 | B51: 46111 | C51: Trần Thị Bình | D51: Hà Nội | E51: SP06 | F51: Văn phòng | G51: 1 | H51: 4500000 | I51: 4500000

Sheet DanhMuc
A1: Mã SP | B1: Tên sản phẩm | C1: Nhóm hàng | D1: Đơn giá | F1: Mã NV | G1: Tên nhân viên | H1: Chi nhánh | J1: Doanh số từ | K1: % Thưởng
A2: SP01 | B2: Laptop Dell Inspiron | C2: Điện tử | D2: 15500000 | F2: NV01 | G2: Nguyễn Văn An | H2: Hà Nội | J2: 0 | K2: 0
A3: SP02 | B3: Chuột Logitech | C3: Phụ kiện | D3: 350000 | F3: NV02 | G3: Trần Thị Bình | H3: Hà Nội | J3: 50000000 | K3: 0.02
A4: SP03 | B4: Bàn phím cơ | C4: Phụ kiện | D4: 1200000 | F4: NV03 | G4: Lê Hoàng Cường | H4: Đà Nẵng | J4: 100000000 | K4: 0.03
A5: SP04 | B5: Màn hình LG 24 inch | C5: Điện tử | D5: 3800000 | F5: NV04 | G5: Phạm Thu Dung | H5: TP.HCM | J5: 200000000 | K5: 0.05
A6: SP05 | B6: Tai nghe Sony | C6: Phụ kiện | D6: 2100000 | F6: NV05 | G6: Hoàng Thị Em | H6: TP.HCM
A7: SP06 | B7: Máy in Canon | C7: Văn phòng | D7: 4500000 | J7: Lưu ý: bảng thưởng sắp xếp TĂNG DẦN — bắt buộc khi dùng VLOOKUP dò gần đúng (TRUE).
A8: SP07 | B8: Giấy A4 (ram) | C8: Văn phòng | D8: 75000
A9: SP08 | B9: Điện thoại Samsung A55 | C9: Điện tử | D9: 9200000

Sheet BT_VLOOKUP
A1: BÀI TẬP VLOOKUP
A2: Cú pháp: =VLOOKUP(giá_trị_tìm, bảng_tìm, cột_thứ_mấy, FALSE/TRUE) • Ô màu VÀNG là chỗ bạn gõ công thức
A4: Phần 1 (Cơ bản): Tra Tên SP và Đơn giá từ DanhMuc!A2:D9, rồi tính Thành tiền = Số lượng × Đơn giá
A5: STT | B5: Mã SP | C5: Số lượng | D5: Tên sản phẩm | E5: Đơn giá | F5: Thành tiền | G5: Kiểm tra
A6: Ví dụ | B6: SP04 | C6: 2 | D6: =VLOOKUP(B6,DanhMuc!$A$2:$D$9,2,FALSE()) -> Màn hình LG 24 inch | E6: =VLOOKUP(B6,DanhMuc!$A$2:$D$9,4,FALSE()) -> 3800000 | F6: =C6*E6 -> 7600000 | G6: ← mẫu, bấm vào ô để xem
A7: 1 | B7: SP02 | C7: 3 | G7: =IF(COUNTBLANK(D7:F7)=3,"",IF(COUNTBLANK(D7:F7)>0,"… làm tiếp",IFERROR(IF(AND(TRIM(D7)=DapAn!$D$5,E7=DapAn!$D$6,F7=DapAn!$D$7),"✔ Đúng","✘ Sai"),"✘ Sai")))
A8: 2 | B8: SP07 | C8: 20 | G8: =IF(COUNTBLANK(D8:F8)=3,"",IF(COUNTBLANK(D8:F8)>0,"… làm tiếp",IFERROR(IF(AND(TRIM(D8)=DapAn!$D$8,E8=DapAn!$D$9,F8=DapAn!$D$10),"✔ Đúng","✘ Sai"),"✘ Sai")))
A9: 3 | B9: SP01 | C9: 1 | G9: =IF(COUNTBLANK(D9:F9)=3,"",IF(COUNTBLANK(D9:F9)>0,"… làm tiếp",IFERROR(IF(AND(TRIM(D9)=DapAn!$D$11,E9=DapAn!$D$12,F9=DapAn!$D$13),"✔ Đúng","✘ Sai"),"✘ Sai")))
A10: 4 | B10: SP05 | C10: 4 | G10: =IF(COUNTBLANK(D10:F10)=3,"",IF(COUNTBLANK(D10:F10)>0,"… làm tiếp",IFERROR(IF(AND(TRIM(D10)=DapAn!$D$14,E10=DapAn!$D$15,F10=DapAn!$D$16),"✔ Đúng","✘ Sai"),"✘ Sai")))
A11: 5 | B11: SP08 | C11: 2 | G11: =IF(COUNTBLANK(D11:F11)=3,"",IF(COUNTBLANK(D11:F11)>0,"… làm tiếp",IFERROR(IF(AND(TRIM(D11)=DapAn!$D$17,E11=DapAn!$D$18,F11=DapAn!$D$19),"✔ Đúng","✘ Sai"),"✘ Sai")))
A12: 6 | B12: SP03 | C12: 5 | G12: =IF(COUNTBLANK(D12:F12)=3,"",IF(COUNTBLANK(D12:F12)>0,"… làm tiếp",IFERROR(IF(AND(TRIM(D12)=DapAn!$D$20,E12=DapAn!$D$21,F12=DapAn!$D$22),"✔ Đúng","✘ Sai"),"✘ Sai")))
A13: 7 | B13: SP06 | C13: 1 | G13: =IF(COUNTBLANK(D13:F13)=3,"",IF(COUNTBLANK(D13:F13)>0,"… làm tiếp",IFERROR(IF(AND(TRIM(D13)=DapAn!$D$23,E13=DapAn!$D$24,F13=DapAn!$D$25),"✔ Đúng","✘ Sai"),"✘ Sai")))
A16: Phần 2 (Trung bình): Tra Tên NV và Chi nhánh từ DanhMuc!F2:H6. Mã không có → dùng IFERROR hiện "Không tìm thấy"
A17: STT | B17: Mã NV | C17: Tên nhân viên | D17: Chi nhánh | E17: Kiểm tra
A18: Ví dụ | B18: NV01 | C18: =IFERROR(VLOOKUP(B18,DanhMuc!$F$2:$H$6,2,FALSE()),"Không tìm thấy") -> Nguyễn Văn An | D18: =IFERROR(VLOOKUP(B18,DanhMuc!$F$2:$H$6,3,FALSE()),"Không tìm thấy") -> Hà Nội | E18: ← mẫu
A19: 1 | B19: NV04 | E19: =IF(COUNTBLANK(C19:D19)=2,"",IF(COUNTBLANK(C19:D19)>0,"… làm tiếp",IF(AND(TRIM(C19)=DapAn!$D$26,TRIM(D19)=DapAn!$D$27),"✔ Đúng","✘ Sai")))
A20: 2 | B20: NV02 | E20: =IF(COUNTBLANK(C20:D20)=2,"",IF(COUNTBLANK(C20:D20)>0,"… làm tiếp",IF(AND(TRIM(C20)=DapAn!$D$28,TRIM(D20)=DapAn!$D$29),"✔ Đúng","✘ Sai")))
A21: 3 | B21: NV09 | E21: =IF(COUNTBLANK(C21:D21)=2,"",IF(COUNTBLANK(C21:D21)>0,"… làm tiếp",IF(AND(TRIM(C21)=DapAn!$D$30,TRIM(D21)=DapAn!$D$31),"✔ Đúng","✘ Sai")))
A22: 4 | B22: NV05 | E22: =IF(COUNTBLANK(C22:D22)=2,"",IF(COUNTBLANK(C22:D22)>0,"… làm tiếp",IF(AND(TRIM(C22)=DapAn!$D$32,TRIM(D22)=DapAn!$D$33),"✔ Đúng","✘ Sai")))
A23: 5 | B23: NV03 | E23: =IF(COUNTBLANK(C23:D23)=2,"",IF(COUNTBLANK(C23:D23)>0,"… làm tiếp",IF(AND(TRIM(C23)=DapAn!$D$34,TRIM(D23)=DapAn!$D$35),"✔ Đúng","✘ Sai")))
A26: Phần 3 (Nâng cao): Tra % thưởng theo doanh số từ DanhMuc!J2:K5 (dò GẦN ĐÚNG → tham số cuối là TRUE), rồi tính Tiền thưởng
A27: STT | B27: Doanh số | C27: % Thưởng | D27: Tiền thưởng | E27: Kiểm tra
A28: Ví dụ | B28: 120000000 | C28: =VLOOKUP(B28,DanhMuc!$J$2:$K$5,2,TRUE()) -> 0.03 | D28: =B28*C28 -> 3600000 | E28: ← mẫu
A29: 1 | B29: 35000000 | E29: =IF(COUNTBLANK(C29:D29)=2,"",IF(COUNTBLANK(C29:D29)>0,"… làm tiếp",IFERROR(IF(AND(ROUND(C29,4)=ROUND(DapAn!$D$36,4),ROUND(D29,0)=ROUND(DapAn!$D$37,0)),"✔ Đúng","✘ Sai"),"✘ Sai")))
A30: 2 | B30: 50000000 | E30: =IF(COUNTBLANK(C30:D30)=2,"",IF(COUNTBLANK(C30:D30)>0,"… làm tiếp",IFERROR(IF(AND(ROUND(C30,4)=ROUND(DapAn!$D$38,4),ROUND(D30,0)=ROUND(DapAn!$D$39,0)),"✔ Đúng","✘ Sai"),"✘ Sai")))
A31: 3 | B31: 99000000 | E31: =IF(COUNTBLANK(C31:D31)=2,"",IF(COUNTBLANK(C31:D31)>0,"… làm tiếp",IFERROR(IF(AND(ROUND(C31,4)=ROUND(DapAn!$D$40,4),ROUND(D31,0)=ROUND(DapAn!$D$41,0)),"✔ Đúng","✘ Sai"),"✘ Sai")))
A32: 4 | B32: 185000000 | E32: =IF(COUNTBLANK(C32:D32)=2,"",IF(COUNTBLANK(C32:D32)>0,"… làm tiếp",IFERROR(IF(AND(ROUND(C32,4)=ROUND(DapAn!$D$42,4),ROUND(D32,0)=ROUND(DapAn!$D$43,0)),"✔ Đúng","✘ Sai"),"✘ Sai")))
A33: 5 | B33: 260000000 | E33: =IF(COUNTBLANK(C33:D33)=2,"",IF(COUNTBLANK(C33:D33)>0,"… làm tiếp",IFERROR(IF(AND(ROUND(C33,4)=ROUND(DapAn!$D$44,4),ROUND(D33,0)=ROUND(DapAn!$D$45,0)),"✔ Đúng","✘ Sai"),"✘ Sai")))

Sheet BT_SUMIFS
A1: BÀI TẬP SUMIFS
A2: Cú pháp: =SUMIFS(vùng_tính_tổng, vùng_đk1, đk1, vùng_đk2, đk2, …) • Dữ liệu ở sheet DuLieu (dòng 2–51) • Ô VÀNG là chỗ bạn gõ công thức
A4: Câu | B4: Mức độ | C4: Câu hỏi | D4: Gợi ý | E4: Đáp án của bạn | F4: Kiểm tra
A5: Ví dụ | B5: Mẫu | C5: Tổng thành tiền của nhân viên Nguyễn Văn An? | D5: Vùng tổng = cột I; vùng đk = cột C | E5: =SUMIFS(DuLieu!$I$2:$I$51,DuLieu!$C$2:$C$51,"Nguyễn Văn An") -> 112700000 | F5: ← mẫu, bấm vào ô để xem
A6: 1 | B6: Cơ bản | C6: Tổng thành tiền của khu vực Hà Nội? | D6: 1 điều kiện: cột Khu vực = "Hà Nội" | F6: =IF(E6="","",IF(ISERROR(ROUND(E6,2)=ROUND(DapAn!$D$46,2)),"✘ Sai",IF(ROUND(E6,2)=ROUND(DapAn!$D$46,2),"✔ Đúng","✘ Sai")))
A7: 2 | B7: Cơ bản | C7: Tổng SỐ LƯỢNG đã bán của sản phẩm SP02? | D7: Vùng tính tổng là cột Số lượng (G) | F7: =IF(E7="","",IF(ISERROR(ROUND(E7,2)=ROUND(DapAn!$D$47,2)),"✘ Sai",IF(ROUND(E7,2)=ROUND(DapAn!$D$47,2),"✔ Đúng","✘ Sai")))
A8: 3 | B8: Cơ bản | C8: Tổng thành tiền nhóm hàng Điện tử? | D8: Điều kiện trên cột Nhóm hàng (F) | F8: =IF(E8="","",IF(ISERROR(ROUND(E8,2)=ROUND(DapAn!$D$48,2)),"✘ Sai",IF(ROUND(E8,2)=ROUND(DapAn!$D$48,2),"✔ Đúng","✘ Sai")))
A9: 4 | B9: Trung bình | C9: Tổng thành tiền của Trần Thị Bình, nhóm Phụ kiện? | D9: 2 điều kiện: Nhân viên + Nhóm hàng | F9: =IF(E9="","",IF(ISERROR(ROUND(E9,2)=ROUND(DapAn!$D$49,2)),"✘ Sai",IF(ROUND(E9,2)=ROUND(DapAn!$D$49,2),"✔ Đúng","✘ Sai")))
A10: 5 | B10: Trung bình | C10: Tổng thành tiền các đơn có số lượng từ 5 trở lên? | D10: Điều kiện so sánh viết trong ngoặc kép: ">=5" | F10: =IF(E10="","",IF(ISERROR(ROUND(E10,2)=ROUND(DapAn!$D$50,2)),"✘ Sai",IF(ROUND(E10,2)=ROUND(DapAn!$D$50,2),"✔ Đúng","✘ Sai")))
A11: 6 | B11: Nâng cao | C11: Tổng thành tiền trong tháng 2/2026? | D11: 2 điều kiện trên CÙNG cột Ngày: ">="&DATE(2026,2,1) và "<"&DATE(2026,3,1) | F11: =IF(E11="","",IF(ISERROR(ROUND(E11,2)=ROUND(DapAn!$D$51,2)),"✘ Sai",IF(ROUND(E11,2)=ROUND(DapAn!$D$51,2),"✔ Đúng","✘ Sai")))
A12: 7 | B12: Nâng cao | C12: Tổng thành tiền khu vực TP.HCM, nhóm Văn phòng, trong tháng 3/2026? | D12: 4 cặp điều kiện | F12: =IF(E12="","",IF(ISERROR(ROUND(E12,2)=ROUND(DapAn!$D$52,2)),"✘ Sai",IF(ROUND(E12,2)=ROUND(DapAn!$D$52,2),"✔ Đúng","✘ Sai")))
A15: Bảng tổng hợp: Doanh thu theo Khu vực × Nhóm hàng
A16: Mẹo: gõ công thức ở ô đầu tiên với $ đúng chỗ (VD $A… và …$17) rồi kéo sang phải và xuống dưới.
A17: Khu vực | B17: Điện tử | C17: Phụ kiện | D17: Văn phòng
A18: Hà Nội
A19: Đà Nẵng
A20: TP.HCM
A21: Kiểm tra bảng: | B21: =IF(COUNT(B18:D20)=0,"",IF(COUNT(B18:D20)<9,"… còn "&(9-COUNT(B18:D20))&" ô trống",IF((ROUND(B18,0)=ROUND(DapAn!$D$53,0))+(ROUND(C18,0)=ROUND(DapAn!$D$54,0))+(ROUND(D18,0)=ROUND(DapAn!$D$55,0))+(ROUND(B19,0)=ROUND(DapAn!$D$56,0))+(ROUND(C19,0)=ROUND(DapAn!$D$57,0))+(ROUND(D19,0)=ROUND(DapAn!$D$58,0))+(ROUND(B20,0)=ROUND(DapAn!$D$59,0))+(ROUND(C20,0)=ROUND(DapAn!$D$60,0))+(ROUND(D20,0)=ROUND(DapAn!$D$61,0))=9,"✔ Đúng hết","✘ Sai "&(9-((ROUND(B18,0)=ROUND(DapAn!$D$53,0))+(ROUND(C18,0)=ROUND(DapAn!$D$54,0))+(ROUND(D18,0)=ROUND(DapAn!$D$55,0))+(ROUND(B19,0)=ROUND(DapAn!$D$56,0))+(ROUND(C19,0)=ROUND(DapAn!$D$57,0))+(ROUND(D19,0)=ROUND(DapAn!$D$58,0))+(ROUND(B20,0)=ROUND(DapAn!$D$59,0))+(ROUND(C20,0)=ROUND(DapAn!$D$60,0))+(ROUND(D20,0)=ROUND(DapAn!$D$61,0))))&" ô")))

Sheet BT_COUNTIFS
A1: BÀI TẬP COUNTIFS
A2: Cú pháp: =COUNTIFS(vùng_đk1, đk1, vùng_đk2, đk2, …) • Dữ liệu ở sheet DuLieu (dòng 2–51) • Ô VÀNG là chỗ bạn gõ công thức
A4: Câu | B4: Mức độ | C4: Câu hỏi | D4: Gợi ý | E4: Đáp án của bạn | F4: Kiểm tra
A5: Ví dụ | B5: Mẫu | C5: Có bao nhiêu đơn ở khu vực Hà Nội? | D5: Đếm số dòng thỏa điều kiện | E5: =COUNTIFS(DuLieu!$D$2:$D$51,"Hà Nội") -> 14 | F5: ← mẫu, bấm vào ô để xem
A6: 1 | B6: Cơ bản | C6: Có bao nhiêu đơn hàng ở khu vực Đà Nẵng? | D6: COUNTIFS không có vùng tính tổng, chỉ có cặp vùng–điều kiện | F6: =IF(E6="","",IF(ISERROR(ROUND(E6,2)=ROUND(DapAn!$D$62,2)),"✘ Sai",IF(ROUND(E6,2)=ROUND(DapAn!$D$62,2),"✔ Đúng","✘ Sai")))
A7: 2 | B7: Cơ bản | C7: Có bao nhiêu đơn bán sản phẩm SP01? | D7: Điều kiện trên cột Mã SP (E) | F7: =IF(E7="","",IF(ISERROR(ROUND(E7,2)=ROUND(DapAn!$D$63,2)),"✘ Sai",IF(ROUND(E7,2)=ROUND(DapAn!$D$63,2),"✔ Đúng","✘ Sai")))
A8: 3 | B8: Cơ bản | C8: Có bao nhiêu đơn có số lượng lớn hơn 3? | D8: ">3" | F8: =IF(E8="","",IF(ISERROR(ROUND(E8,2)=ROUND(DapAn!$D$64,2)),"✘ Sai",IF(ROUND(E8,2)=ROUND(DapAn!$D$64,2),"✔ Đúng","✘ Sai")))
A9: 4 | B9: Trung bình | C9: Số đơn của Lê Hoàng Cường thuộc nhóm Điện tử? | D9: 2 điều kiện | F9: =IF(E9="","",IF(ISERROR(ROUND(E9,2)=ROUND(DapAn!$D$65,2)),"✘ Sai",IF(ROUND(E9,2)=ROUND(DapAn!$D$65,2),"✔ Đúng","✘ Sai")))
A10: 5 | B10: Trung bình | C10: Số đơn trong tháng 1/2026? | D10: Ngày >= 1/1/2026 và < 1/2/2026 | F10: =IF(E10="","",IF(ISERROR(ROUND(E10,2)=ROUND(DapAn!$D$66,2)),"✘ Sai",IF(ROUND(E10,2)=ROUND(DapAn!$D$66,2),"✔ Đúng","✘ Sai")))
A11: 6 | B11: Nâng cao | C11: Số đơn có thành tiền từ 5.000.000 đến 20.000.000? | D11: 2 điều kiện trên cùng cột I: ">=5000000" và "<=20000000" | F11: =IF(E11="","",IF(ISERROR(ROUND(E11,2)=ROUND(DapAn!$D$67,2)),"✘ Sai",IF(ROUND(E11,2)=ROUND(DapAn!$D$67,2),"✔ Đúng","✘ Sai")))
A12: 7 | B12: Nâng cao | C12: Số đơn do nhân viên có chữ "Thị" trong tên bán? | D12: Ký tự đại diện: "*Thị*" | F12: =IF(E12="","",IF(ISERROR(ROUND(E12,2)=ROUND(DapAn!$D$68,2)),"✘ Sai",IF(ROUND(E12,2)=ROUND(DapAn!$D$68,2),"✔ Đúng","✘ Sai")))
A15: Bảng tổng hợp: Số đơn theo Nhân viên × Nhóm hàng
A16: Mẹo: gõ công thức ở ô đầu tiên với $ đúng chỗ (VD $A… và …$17) rồi kéo sang phải và xuống dưới.
A17: Nhân viên | B17: Điện tử | C17: Phụ kiện | D17: Văn phòng
A18: Nguyễn Văn An
A19: Trần Thị Bình
A20: Lê Hoàng Cường
A21: Phạm Thu Dung
A22: Hoàng Thị Em
A23: Kiểm tra bảng: | B23: =IF(COUNT(B18:D22)=0,"",IF(COUNT(B18:D22)<15,"… còn "&(15-COUNT(B18:D22))&" ô trống",IF((ROUND(B18,0)=ROUND(DapAn!$D$69,0))+(ROUND(C18,0)=ROUND(DapAn!$D$70,0))+(ROUND(D18,0)=ROUND(DapAn!$D$71,0))+(ROUND(B19,0)=ROUND(DapAn!$D$72,0))+(ROUND(C19,0)=ROUND(DapAn!$D$73,0))+(ROUND(D19,0)=ROUND(DapAn!$D$74,0))+(ROUND(B20,0)=ROUND(DapAn!$D$75,0))+(ROUND(C20,0)=ROUND(DapAn!$D$76,0))+(ROUND(D20,0)=ROUND(DapAn!$D$77,0))+(ROUND(B21,0)=ROUND(DapAn!$D$78,0))+(ROUND(C21,0)=ROUND(DapAn!$D$79,0))+(ROUND(D21,0)=ROUND(DapAn!$D$80,0))+(ROUND(B22,0)=ROUND(DapAn!$D$81,0))+(ROUND(C22,0)=ROUND(DapAn!$D$82,0))+(ROUND(D22,0)=ROUND(DapAn!$D$83,0))=15,"✔ Đúng hết","✘ Sai "&(15-((ROUND(B18,0)=ROUND(DapAn!$D$69,0))+(ROUND(C18,0)=ROUND(DapAn!$D$70,0))+(ROUND(D18,0)=ROUND(DapAn!$D$71,0))+(ROUND(B19,0)=ROUND(DapAn!$D$72,0))+(ROUND(C19,0)=ROUND(DapAn!$D$73,0))+(ROUND(D19,0)=ROUND(DapAn!$D$74,0))+(ROUND(B20,0)=ROUND(DapAn!$D$75,0))+(ROUND(C20,0)=ROUND(DapAn!$D$76,0))+(ROUND(D20,0)=ROUND(DapAn!$D$77,0))+(ROUND(B21,0)=ROUND(DapAn!$D$78,0))+(ROUND(C21,0)=ROUND(DapAn!$D$79,0))+(ROUND(D21,0)=ROUND(DapAn!$D$80,0))+(ROUND(B22,0)=ROUND(DapAn!$D$81,0))+(ROUND(C22,0)=ROUND(DapAn!$D$82,0))+(ROUND(D22,0)=ROUND(DapAn!$D$83,0))))&" ô")))

Sheet DapAn
A1: ĐÁP ÁN — chỉ mở khi đã tự làm xong!
A2: Cột C là công thức mẫu (gõ trong sheet bài tập), cột D là kết quả đúng.
A4: Phần | B4: Câu / Ô | C4: Công thức mẫu | D4: Kết quả
A5: VLOOKUP P1 | B5: Câu 1 – Tên SP (D7) | C5: =VLOOKUP(B7,DanhMuc!$A$2:$D$9,2,FALSE) | D5: =VLOOKUP(BT_VLOOKUP!B7,DanhMuc!$A$2:$D$9,2,FALSE()) -> Chuột Logitech
A6: VLOOKUP P1 | B6: Câu 1 – Đơn giá (E7) | C6: =VLOOKUP(B7,DanhMuc!$A$2:$D$9,4,FALSE) | D6: =VLOOKUP(BT_VLOOKUP!B7,DanhMuc!$A$2:$D$9,4,FALSE()) -> 350000
A7: VLOOKUP P1 | B7: Câu 1 – Thành tiền (F7) | C7: =C7*VLOOKUP(B7,DanhMuc!$A$2:$D$9,4,FALSE) | D7: =BT_VLOOKUP!C7*VLOOKUP(BT_VLOOKUP!B7,DanhMuc!$A$2:$D$9,4,FALSE()) -> 1050000
A8: VLOOKUP P1 | B8: Câu 2 – Tên SP (D8) | C8: =VLOOKUP(B8,DanhMuc!$A$2:$D$9,2,FALSE) | D8: =VLOOKUP(BT_VLOOKUP!B8,DanhMuc!$A$2:$D$9,2,FALSE()) -> Giấy A4 (ram)
A9: VLOOKUP P1 | B9: Câu 2 – Đơn giá (E8) | C9: =VLOOKUP(B8,DanhMuc!$A$2:$D$9,4,FALSE) | D9: =VLOOKUP(BT_VLOOKUP!B8,DanhMuc!$A$2:$D$9,4,FALSE()) -> 75000
A10: VLOOKUP P1 | B10: Câu 2 – Thành tiền (F8) | C10: =C8*VLOOKUP(B8,DanhMuc!$A$2:$D$9,4,FALSE) | D10: =BT_VLOOKUP!C8*VLOOKUP(BT_VLOOKUP!B8,DanhMuc!$A$2:$D$9,4,FALSE()) -> 1500000
A11: VLOOKUP P1 | B11: Câu 3 – Tên SP (D9) | C11: =VLOOKUP(B9,DanhMuc!$A$2:$D$9,2,FALSE) | D11: =VLOOKUP(BT_VLOOKUP!B9,DanhMuc!$A$2:$D$9,2,FALSE()) -> Laptop Dell Inspiron
A12: VLOOKUP P1 | B12: Câu 3 – Đơn giá (E9) | C12: =VLOOKUP(B9,DanhMuc!$A$2:$D$9,4,FALSE) | D12: =VLOOKUP(BT_VLOOKUP!B9,DanhMuc!$A$2:$D$9,4,FALSE()) -> 15500000
A13: VLOOKUP P1 | B13: Câu 3 – Thành tiền (F9) | C13: =C9*VLOOKUP(B9,DanhMuc!$A$2:$D$9,4,FALSE) | D13: =BT_VLOOKUP!C9*VLOOKUP(BT_VLOOKUP!B9,DanhMuc!$A$2:$D$9,4,FALSE()) -> 15500000
A14: VLOOKUP P1 | B14: Câu 4 – Tên SP (D10) | C14: =VLOOKUP(B10,DanhMuc!$A$2:$D$9,2,FALSE) | D14: =VLOOKUP(BT_VLOOKUP!B10,DanhMuc!$A$2:$D$9,2,FALSE()) -> Tai nghe Sony
A15: VLOOKUP P1 | B15: Câu 4 – Đơn giá (E10) | C15: =VLOOKUP(B10,DanhMuc!$A$2:$D$9,4,FALSE) | D15: =VLOOKUP(BT_VLOOKUP!B10,DanhMuc!$A$2:$D$9,4,FALSE()) -> 2100000
A16: VLOOKUP P1 | B16: Câu 4 – Thành tiền (F10) | C16: =C10*VLOOKUP(B10,DanhMuc!$A$2:$D$9,4,FALSE) | D16: =BT_VLOOKUP!C10*VLOOKUP(BT_VLOOKUP!B10,DanhMuc!$A$2:$D$9,4,FALSE()) -> 8400000
A17: VLOOKUP P1 | B17: Câu 5 – Tên SP (D11) | C17: =VLOOKUP(B11,DanhMuc!$A$2:$D$9,2,FALSE) | D17: =VLOOKUP(BT_VLOOKUP!B11,DanhMuc!$A$2:$D$9,2,FALSE()) -> Điện thoại Samsung A55
A18: VLOOKUP P1 | B18: Câu 5 – Đơn giá (E11) | C18: =VLOOKUP(B11,DanhMuc!$A$2:$D$9,4,FALSE) | D18: =VLOOKUP(BT_VLOOKUP!B11,DanhMuc!$A$2:$D$9,4,FALSE()) -> 9200000
A19: VLOOKUP P1 | B19: Câu 5 – Thành tiền (F11) | C19: =C11*VLOOKUP(B11,DanhMuc!$A$2:$D$9,4,FALSE) | D19: =BT_VLOOKUP!C11*VLOOKUP(BT_VLOOKUP!B11,DanhMuc!$A$2:$D$9,4,FALSE()) -> 18400000
A20: VLOOKUP P1 | B20: Câu 6 – Tên SP (D12) | C20: =VLOOKUP(B12,DanhMuc!$A$2:$D$9,2,FALSE) | D20: =VLOOKUP(BT_VLOOKUP!B12,DanhMuc!$A$2:$D$9,2,FALSE()) -> Bàn phím cơ
A21: VLOOKUP P1 | B21: Câu 6 – Đơn giá (E12) | C21: =VLOOKUP(B12,DanhMuc!$A$2:$D$9,4,FALSE) | D21: =VLOOKUP(BT_VLOOKUP!B12,DanhMuc!$A$2:$D$9,4,FALSE()) -> 1200000
A22: VLOOKUP P1 | B22: Câu 6 – Thành tiền (F12) | C22: =C12*VLOOKUP(B12,DanhMuc!$A$2:$D$9,4,FALSE) | D22: =BT_VLOOKUP!C12*VLOOKUP(BT_VLOOKUP!B12,DanhMuc!$A$2:$D$9,4,FALSE()) -> 6000000
A23: VLOOKUP P1 | B23: Câu 7 – Tên SP (D13) | C23: =VLOOKUP(B13,DanhMuc!$A$2:$D$9,2,FALSE) | D23: =VLOOKUP(BT_VLOOKUP!B13,DanhMuc!$A$2:$D$9,2,FALSE()) -> Máy in Canon
A24: VLOOKUP P1 | B24: Câu 7 – Đơn giá (E13) | C24: =VLOOKUP(B13,DanhMuc!$A$2:$D$9,4,FALSE) | D24: =VLOOKUP(BT_VLOOKUP!B13,DanhMuc!$A$2:$D$9,4,FALSE()) -> 4500000
A25: VLOOKUP P1 | B25: Câu 7 – Thành tiền (F13) | C25: =C13*VLOOKUP(B13,DanhMuc!$A$2:$D$9,4,FALSE) | D25: =BT_VLOOKUP!C13*VLOOKUP(BT_VLOOKUP!B13,DanhMuc!$A$2:$D$9,4,FALSE()) -> 4500000
A26: VLOOKUP P2 | B26: Câu 1 – Tên NV (C19) | C26: =IFERROR(VLOOKUP(B19,DanhMuc!$F$2:$H$6,2,FALSE),"Không tìm thấy") | D26: =IFERROR(VLOOKUP(BT_VLOOKUP!B19,DanhMuc!$F$2:$H$6,2,FALSE()),"Không tìm thấy") -> Phạm Thu Dung
A27: VLOOKUP P2 | B27: Câu 1 – Chi nhánh (D19) | C27: =IFERROR(VLOOKUP(B19,DanhMuc!$F$2:$H$6,3,FALSE),"Không tìm thấy") | D27: =IFERROR(VLOOKUP(BT_VLOOKUP!B19,DanhMuc!$F$2:$H$6,3,FALSE()),"Không tìm thấy") -> TP.HCM
A28: VLOOKUP P2 | B28: Câu 2 – Tên NV (C20) | C28: =IFERROR(VLOOKUP(B20,DanhMuc!$F$2:$H$6,2,FALSE),"Không tìm thấy") | D28: =IFERROR(VLOOKUP(BT_VLOOKUP!B20,DanhMuc!$F$2:$H$6,2,FALSE()),"Không tìm thấy") -> Trần Thị Bình
A29: VLOOKUP P2 | B29: Câu 2 – Chi nhánh (D20) | C29: =IFERROR(VLOOKUP(B20,DanhMuc!$F$2:$H$6,3,FALSE),"Không tìm thấy") | D29: =IFERROR(VLOOKUP(BT_VLOOKUP!B20,DanhMuc!$F$2:$H$6,3,FALSE()),"Không tìm thấy") -> Hà Nội
A30: VLOOKUP P2 | B30: Câu 3 – Tên NV (C21) | C30: =IFERROR(VLOOKUP(B21,DanhMuc!$F$2:$H$6,2,FALSE),"Không tìm thấy") | D30: =IFERROR(VLOOKUP(BT_VLOOKUP!B21,DanhMuc!$F$2:$H$6,2,FALSE()),"Không tìm thấy") -> Không tìm thấy
A31: VLOOKUP P2 | B31: Câu 3 – Chi nhánh (D21) | C31: =IFERROR(VLOOKUP(B21,DanhMuc!$F$2:$H$6,3,FALSE),"Không tìm thấy") | D31: =IFERROR(VLOOKUP(BT_VLOOKUP!B21,DanhMuc!$F$2:$H$6,3,FALSE()),"Không tìm thấy") -> Không tìm thấy
A32: VLOOKUP P2 | B32: Câu 4 – Tên NV (C22) | C32: =IFERROR(VLOOKUP(B22,DanhMuc!$F$2:$H$6,2,FALSE),"Không tìm thấy") | D32: =IFERROR(VLOOKUP(BT_VLOOKUP!B22,DanhMuc!$F$2:$H$6,2,FALSE()),"Không tìm thấy") -> Hoàng Thị Em
A33: VLOOKUP P2 | B33: Câu 4 – Chi nhánh (D22) | C33: =IFERROR(VLOOKUP(B22,DanhMuc!$F$2:$H$6,3,FALSE),"Không tìm thấy") | D33: =IFERROR(VLOOKUP(BT_VLOOKUP!B22,DanhMuc!$F$2:$H$6,3,FALSE()),"Không tìm thấy") -> TP.HCM
A34: VLOOKUP P2 | B34: Câu 5 – Tên NV (C23) | C34: =IFERROR(VLOOKUP(B23,DanhMuc!$F$2:$H$6,2,FALSE),"Không tìm thấy") | D34: =IFERROR(VLOOKUP(BT_VLOOKUP!B23,DanhMuc!$F$2:$H$6,2,FALSE()),"Không tìm thấy") -> Lê Hoàng Cường
A35: VLOOKUP P2 | B35: Câu 5 – Chi nhánh (D23) | C35: =IFERROR(VLOOKUP(B23,DanhMuc!$F$2:$H$6,3,FALSE),"Không tìm thấy") | D35: =IFERROR(VLOOKUP(BT_VLOOKUP!B23,DanhMuc!$F$2:$H$6,3,FALSE()),"Không tìm thấy") -> Đà Nẵng
A36: VLOOKUP P3 | B36: Câu 1 – % thưởng (C29) | C36: =VLOOKUP(B29,DanhMuc!$J$2:$K$5,2,TRUE) | D36: =VLOOKUP(BT_VLOOKUP!B29,DanhMuc!$J$2:$K$5,2,TRUE()) -> 0
A37: VLOOKUP P3 | B37: Câu 1 – Tiền thưởng (D29) | C37: =B29*VLOOKUP(B29,DanhMuc!$J$2:$K$5,2,TRUE) | D37: =BT_VLOOKUP!B29*VLOOKUP(BT_VLOOKUP!B29,DanhMuc!$J$2:$K$5,2,TRUE()) -> 0
A38: VLOOKUP P3 | B38: Câu 2 – % thưởng (C30) | C38: =VLOOKUP(B30,DanhMuc!$J$2:$K$5,2,TRUE) | D38: =VLOOKUP(BT_VLOOKUP!B30,DanhMuc!$J$2:$K$5,2,TRUE()) -> 0.02
A39: VLOOKUP P3 | B39: Câu 2 – Tiền thưởng (D30) | C39: =B30*VLOOKUP(B30,DanhMuc!$J$2:$K$5,2,TRUE) | D39: =BT_VLOOKUP!B30*VLOOKUP(BT_VLOOKUP!B30,DanhMuc!$J$2:$K$5,2,TRUE()) -> 1000000
A40: VLOOKUP P3 | B40: Câu 3 – % thưởng (C31) | C40: =VLOOKUP(B31,DanhMuc!$J$2:$K$5,2,TRUE) | D40: =VLOOKUP(BT_VLOOKUP!B31,DanhMuc!$J$2:$K$5,2,TRUE()) -> 0.02
A41: VLOOKUP P3 | B41: Câu 3 – Tiền thưởng (D31) | C41: =B31*VLOOKUP(B31,DanhMuc!$J$2:$K$5,2,TRUE) | D41: =BT_VLOOKUP!B31*VLOOKUP(BT_VLOOKUP!B31,DanhMuc!$J$2:$K$5,2,TRUE()) -> 1980000
...
